Workbook
Name BE_Total: #REF!
Name BE_Variable: #REF!
Name Suvartota_pašarams: #REF!
Name Table_total: #REF!
Name Revenue_increments: #REF!
Name Table_Variable: #REF!
Name Suvartota_sėklai: #REF!
Name Derlingumas: #REF!
Name Fixed_expenses: #REF!
Name Atsargos_t: #REF!
Name korekcijos_faktor: #REF!
Name Atsargos_t: #REF!
Name Pirkta_produkcija: #REF!
Name BE_Revenue: #REF!
Name Revenue_increments: #REF!
Name Contribution_margin: #REF!
Name Table_Revenue: #REF!
Name Parduota_natūra: #REF!
Name BE_Fixed: #REF!
Name Pardavimai_Lt: #REF!
Name ats: #REF!
Name Atsargos_t: #REF!
Name ats: #REF!
Name Atsargos_t: #REF!
Name Pardavimai_užskaitoma: #REF!
Name Table_Fixed: #REF!
Name Revenue_increments: #REF!
Name Derlius: #REF!
Name Išlaidos_Lt: #REF!
Name ats: #REF!
Name Plotas: #REF!
Name Kainos: #REF!
Name ats: #REF!
Name Revenue_increments: #REF!
Name korekcijos_faktor2: #REF!
Name Išlaikymo_nuostoliai: #REF!

Sheet Invesment
D2: 1 scenario | G2: 2 scenario
B3: Project value and funding sources, EUR | C3: EUR, without VAT | F3: EUR, without VAT
C4: Total | D4: 2018 | E4: 2019 | F4: Total | G4: 2018 | H4: 2019
B5: Investments in fixed assets - equipment | C5: 1528273.2 | D5: =C5*0.4 -> 611309.28 | E5: =C5*0.6 -> 916963.92 | F5: 0 | G5: =F5*0.4 -> 0 | H5: =F5*0.6 -> 0
B6: Investments in fixed assets - buildings | C6: 3000000 | E6: =C6 -> 3000000
B7: Salary of the project implementation team | C7: 140000 | D7: =C7*0.4 -> 56000 | E7: =C7*0.6 -> 84000 | F7: 0 | G7: =F7*0.4 -> 0 | H7: =F7*0.6 -> 0
B8: Purchase of services | C8: 750000 | D8: =C8*0.5 -> 375000 | E8: =D8 -> 375000 | F8: 8000000 | G8: =F8*0.5 -> 4000000 | H8: =G8 -> 4000000
B9: Total value of the project | C9: =SUM(C5:C8) -> 5418273.2 | D9: =SUM(D5:D8) -> 1042309.3 | E9: =SUM(E5:E8) -> 4375963.9 | F9: =SUM(F5:F8) -> 8000000 | G9: =SUM(G5:G8) -> 4000000 | H9: =SUM(H5:H8) -> 4000000
B11: Private investment (third party) | C11: 1200000 | D11: =C11-E11 -> 500000 | E11: 700000 | F11: 0 | G11: 0 | H11: 0
B12: Own funds | C12: =C9-C11-C13 -> 2718273.2 | D12: =D9-D11-D13 -> 92309.28 | E12: =E9-E11-E13 -> 2625963.9 | F12: =F9-F11-F13 -> 8000000 | G12: =G9-G11-G13 -> 4000000 | H12: =H9-H11-H13 -> 4000000
B13: Financing of credit institutions | C13: 1500000 | D13: =C13*0.3 -> 450000 | E13: =C13-D13 -> 1050000 | F13: 0 | G13: =F13*0.4 -> 0 | H13: =F13*0.6 -> 0
B14: Project funding sources, total | C14: =SUM(C11:C13) -> 5418273.2 | D14: =SUM(D11:D13) -> 1042309.3 | E14: =SUM(E11:E13) -> 4375963.9 | F14: =SUM(F11:F13) -> 8000000 | G14: =SUM(G11:G13) -> 4000000 | H14: =SUM(H11:H13) -> 4000000
C15: =C14-C9 -> 0 | D15: =D14-D9 -> 0 | E15: =E14-E9 -> 0 | F15: =F14-F9 -> 0 | G15: =G14-G9 -> 0 | H15: =H14-H9 -> 0
B17: Loan terms
B18: Private investment
B19: Duration - 5 years, interest rate - 5 percent.
B20: Refund - at expiration.
B22: Bank loan
B23: Duration - 3 years, interest rate - 3 percent.
B24: Repayment - a yearly loan balance of EUR 500,000 is repaid..

Sheet Income Statement
C2: Statement of profit or loss(Income Statement), EUR
C3: Articles | D3: 2016 | E3: 2017
B5: I. | C5: SALES REVENUE | D5: 2714177.5 | E5: 4414253.6
B6: II. | C6: COST OF SALES | D6: 998289.54 | E6: 1121942.5
C7: COGS Ratio | E7: =E6/E5 -> 0.25416357
C8: Depreciation and amortization | D8: 0 | E8: 0
C9: Materials (raw materials) | D9: 992551.55 | E9: 1076892.7
C10: Wage
C11: Rental of industrial premises
C12: Others | D12: 5737.9852 | E12: 45049.815
B13: III. | C13: GROSS PROFIT (LOSS) | D13: =SUM(D5-D6) -> 1715887.9 | E13: =SUM(E5-E6) -> 3292311.2
B14: IV. | C14: OPERATING COSTS | D14: =SUM(D15,D20) -> 1367820.1 | E14: =SUM(E15,E20) -> 2932586.3
B15: IV.1 | C15: For sale | D15: 726794.2 | E15: =sum(E18:E19) -> 534191.72
C16: Depreciation and amortization
C17: Wage
C18: Marketing | D18: 352544 | E18: 523344
C19: Others | D19: 374250.2 | E19: 10847.718
B20: IV.2 | C20: General and administrative | D20: =SUM(D21:D24) -> 641025.87 | E20: =SUM(E21:E24) -> 2398394.6
C21: Depreciation and amortization | D21: 140511.18 | E21: 203121.81
C22: Wage | D22: 499966.69 | E22: 1368507
C23: Rent of premises
C24: Others | D24: 548 | E24: 826765.77
B25: V. | C25: OPERATING PROFIT | D25: =SUM(D13-D14) -> 348067.87 | E25: =SUM(E13-E14) -> 359724.86
B26: VI. | C26: ANOTHER ACTIVITY | D26: =SUM(D27-D28) -> 4344.3003 | E26: =SUM(E27-E28) -> 89548.193
B27: VI.1. | C27: Income | D27: =15000/3.4528 -> 4344.3003 | E27: =309192/3.4528 -> 89548.193
B28: VI.2. | C28: Costs | D28: 0 | E28: 0
B29: VII. | C29: FINANCING AND INVESTING ACTIVITIES | D29: =SUM(D30-D31) -> -9701.1121 | E29: =SUM(E30-E31) -> -21799.12
B30: VII.1. | C30: Income | D30: =11633/3.4528 -> 3369.1497 | E30: =9444/3.4528 -> 2735.1715
B31: VII.2. | C31: Costs | D31: =45129/3.4528 -> 13070.262 | E31: =84712/3.4528 -> 24534.291
B32: X. | C32: LOSSES
B33: XI. | C33: PROFIT (LOSS) BEFORE TAX | D33: 342711.06 | E33: 427473.93
B34: XII. | C34: INCOME TAX | D34: 54291.01 | E34: 62089.608
C35: TAX % | D35: =D34/D33 -> 0.15841628 | E35: =E34/E33 -> 0.14524771
B36: XIII. | C36: NET PROFIT (LOSS) | D36: 288420.05 | E36: 365384.33
D38: 0 | E38: 0

Sheet Balance sheet
B3: Articles | C3: Actual
C4: 2016 | D4: 2017
B5: FIXED ASSETS | C5: 1321427 | D5: 1249622.9
B6: INTANGIBLE ASSETS | C6: 1345.5746 | D6: 1572.6367
B7: Patents and licenses | C7: 0 | D7: 0
B8: software | C8: 0 | D8: 0
B9: Other current assets | C9: 1345.5746 | D9: 1572.6367
B10: TANGIBLE ASSETS | C10: 1184828.8 | D10: 1098770
B11: Land | C11: 0 | D11: 0
B12: Buildings and structures | C12: 728233.61 | D12: 585547.38
B13: Machinery and equipment | C13: 323297.03 | D13: 222930.95
B14: Vehicles | C14: 130161.32 | D14: 249225.56
B15: Other equipment, tools and installations | C15: 3136.8744 | D15: 41066.091
B16: Construction work in progress | C16: 0 | D16: 0
... B45: Profit (loss) for the previous year | C45: 164753.03 | D45: 453173.08
C46: 0 | D46: 0
B47: GRANTS AND SUBSIDIES | C47: 0 | D47: 0
C48: 0 | D48: 0
B49: PAYMENT SUMS AND LIABILITIES | C49: 1281872.7 | D49: 947969.61
B50: AMOUNTS PAYABLE AFTER ONE YEAR AND NON-CURRENT LIABILITIES | C50: 523639.37 | D50: 105177.83
B51: Financial debts | C51: 394759.04 | D51: 0
B52: Other debts | C52: 75011.006 | D52: 105177.83
B53: Other | C53: 53869.323 | D53: 0
B54: AMOUNTS PAYABLE WITHIN ONE YEAR AND CURRENT LIABILITIES | C54: 758233.32 | D54: 842791.78
B55: Current part of long - term debt | C55: 42556.476 | D55: 54738.473
B56: Financial debts | C56: 89784.523 | D56: 0
B57: Debts to suppliers | C57: 267060.07 | D57: 391348.47
B58: Other | C58: 358832.25 | D58: 396704.83
B59: TOTAL EQUITY AND LIABILITIES: | C59: 1738231.6 | D59: 1769712.8

Sheet Cash flows
B2: Articles | C2: Actual
C3: 2016 | D3: 2017
B4: Cash inflow (including VAT): | C4: =SUM(C5:C6) -> 3418804.8 | D4: =SUM(D5:D6) -> 5477916.7
B5: From customers | C5: ='Income Statement'!D5*1.21 -> 3284154.8 | D5: ='Income Statement'!E5*1.21 -> 5341246.9
B6: Others | C6: 134650 | D6: =C6*1.015 -> 136669.75
B7: Cash benefits: | C7: =SUM(C8:C11) -> -2865267.3 | D7: =SUM(D8:D11) -> -4917989.9
B8: Money paid to suppliers | C8: -2232103.6 | D8: -3598006.6
B9: For wages | C9: -499966.69 | D9: -1368507
B10: Fees paid | C10: -238 | D10: 70322.795
B11: Other benefits | C11: -132959 | D11: -21799.12
B12: Net cash flows from manufacturing activities | C12: =C4+C7 -> 553537.42 | D12: =D4+D7 -> 559926.73
B14: Acquisition of fixed assets | C14: -351467.22 | D14: -243493.98
B15: Transfer of fixed assets | C15: 0 | D15: 291013.38
B16: Other cash flows from investing activities (listed) | C16: -131719.18 | D16: -14027.746
B17: Net cash flows from investing activities | C17: =SUM(C14:C16) -> -483186.4 | D17: =SUM(D14:D16) -> 33491.659
B19: Shareholders' contributions | C19: 0 | D19: 0
B20: Dividends are paid
B21: Obtaining loans | C21: 53869.323 | D21: 0
B22: Repayment of loans | C22: -56671.687 | D22: -576913.23
B23: Interest paid | C23: -11716.867 | D23: -13756.372
B24: Other cash flows from financing activities | C24: 2253.5334 | D24: -7818.0028
B25: Net cash flows from financing activities | C25: =SUM(C19:C24) -> -12265.697 | D25: =SUM(D19:D24) -> -598487.6
B27: Cash flow | C27: =SUM(C25,C17,C12) -> 58085.322 | D27: =SUM(D25,D17,D12) -> -5069.2192
B28: Amount of money at the beginning of the year | C28: 127541.71 | D28: =C29 -> 185627.03
B29: Amount of money at the end of the year | C29: =C28+C27 -> 185627.03 | D29: =D28+D27 -> 180557.81
B31: Check | C31: 5.8207661e-10 | D31: -2.3283064e-10
C32: =C29-'Balance sheet'!C31 -> 5.2386895e-10 | D32: =D29-'Balance sheet'!D31 -> -2.3283064e-10

Sheet Scenario1 vs Scenario2
A1: Scenario 1 (Build a factory) | K1: Key assumptions:
B2: 2017(Actual) | C2: 2018(Proj. invest) | D2: 2019(Proj. invest) | E2: 2020(Proj.) | F2: 2021(Proj.) | G2: 2022(Proj.) | H2: 2023(Proj.) | I2: 2024(Proj.) | K2: Average Salary: Based on a total wage expense of €1,368,507 for 60 employees | L2: 22808
B3: Baseline | C3: 0 | D3: 1 | E3: 2 | F3: 3 | G3: 4 | H3: 5 | I3: 6 | K3: Cost of Sales (COGS) Ratio (of sales revenue): | L3: ='Income Statement'!E6/'Income Statement'!E5 -> 0.25416357
A4: Base sales revenue | B4: =B5 -> 4414253.6 | C4: =B4*1.1 -> 4855679 | D4: =C4*1.1 -> 5341246.9 | E4: =D4*1.1 -> 5875371.6 | F4: =E4*1.1 -> 6462908.8 | G4: =F4*1.1 -> 7109199.6 | H4: =G4*1.1 -> 7820119.6 | I4: =H4*1.1 -> 8602131.6 | K4: Tax Rate: | L4: 15% (based on 2016-2017).
A5: Project Sales Revenue | B5: ='Income Statement'!E5 -> 4414253.6 | C5: =B5*1.1 -> 4855679 | D5: =C5*1.1 -> 5341246.9 | E5: =E4*1.5 -> 8813057.4 | F5: =E5*1.1 -> 9694363.2 | G5: =F5*1.1 -> 10663799 | H5: =G5*1.1 -> 11730179 | I5: =H5*1.1 -> 12903197 | K5: Discount Rate: | L5: 0.1
A6: Revenue Growth % | B6: =#REF!/B5 -> #REF! | C6: 10% (Building) | D6: 10% (Building) | E6: 0.5 | F6: =+10% -> 0.1 | G6: =+10% -> 0.1 | H6: =+10% -> 0.1 | I6: =+10% -> 0.1 | K6: Evaluation: | L6: 7 years (2018–2024)
A7: Incremental Revenue | C7: =C5-C4 -> 0 | D7: =D5-D4 -> 0 | E7: =E5-E4 -> 2937685.8 | F7: =F5-F4 -> 3231454.4 | G7: =G5-G4 -> 3554599.8 | H7: =H5-H4 -> 3910059.8 | I7: =I5-I4 -> 4301065.8 | K7: Incremental Marketing | L7: 0.1185
A8: Incremental COGS 25.42% | E8: =-E7*$L$3 -> -746652.72 | F8: =-F7*$L$3 -> -821317.99 | G8: =-G7*$L$3 -> -903449.79 | H8: =-H7*$L$3 -> -993794.77 | I8: =-I7*$L$3 -> -1093174.2 | K8: Baseline company sales grow at 10% per year.
A9: Incremental Marketing (11.85%) | E9: =-E7*$L$7 -> -348115.77 | F9: =-F7*$L$7 -> -382927.34 | G9: =-G7*$L$7 -> -421220.08 | H9: =-H7*$L$7 -> -463342.09 | I9: =-I7*$L$7 -> -509676.3
A10: Total Variable Costs (37.272%) | E10: =SUM(E8:E9) -> -1094768.5 | F10: =SUM(F8:F9) -> -1204245.3 | G10: =SUM(G8:G9) -> -1324669.9 | H10: =SUM(H8:H9) -> -1457136.9 | I10: =SUM(I8:I9) -> -1602850.5
A11: Salary Expense | E11: =-$L$2*10 -> -228080 | F11: =-$L$2*10 -> -228080 | G11: =-$L$2*10 -> -228080 | H11: =-$L$2*10 -> -228080 | I11: =-$L$2*10 -> -228080
A12: Incremental EBITDA | E12: =E7+E10+E11 -> 1614837.3 | F12: =F7+F10+F11 -> 1799129 | G12: =G7+G10+G11 -> 2001849.9 | H12: =H7+H10+H11 -> 2224842.9 | I12: =I7+I10+I11 -> 2470135.2
A13: Depreciation(15 years) | E13: =-sum(Invesment!$D$5,Invesment!$E$5,Invesment!$E$6)/15 -> -301884.88 | F13: =-sum(Invesment!$D$5,Invesment!$E$5,Invesment!$E$6)/15 -> -301884.88 | G13: =-sum(Invesment!$D$5,Invesment!$E$5,Invesment!$E$6)/15 -> -301884.88 | H13: =-sum(Invesment!$D$5,Invesment!$E$5,Invesment!$E$6)/15 -> -301884.88 | I13: =-sum(Invesment!$D$5,Invesment!$E$5,Invesment!$E$6)/15 -> -301884.88
A14: EBIT | E14: =E12+E13 -> 1312952.4 | F14: =F12+F13 -> 1497244.2 | G14: =G12+G13 -> 1699965.1 | H14: =H12+H13 -> 1922958.1 | I14: =I12+I13 -> 2168250.4
A15: TAX 15% | E15: =-E14*0.15 -> -196942.87 | F15: =-F14*0.15 -> -224586.62 | G15: =-G14*0.15 -> -254994.76 | H15: =-H14*0.15 -> -288443.71 | I15: =-I14*0.15 -> -325237.55
A16: Net Operating Profit After Tax | E16: =E14+E15 -> 1116009.6 | F16: =F14+F15 -> 1272657.5 | G16: =G14+G15 -> 1444970.3 | H16: =H14+H15 -> 1634514.4 | I16: =I14+I15 -> 1843012.8
A17: Working capital (10%) | E17: =E7*0.1 -> 293768.58 | F17: =($F$7*0.1)-E17 -> 29376.858 | G17: =G7*0.1-F7*0.1 -> 32314.544 | H17: =H7*0.1-G7*0.1 -> 35545.998 | I17: =0-H7*0.1 -> -391005.98
A18: CapEx (project costs) | C18: =-Invesment!D14 -> -1042309.3 | D18: =-Invesment!E14 -> -4375963.9
A19: FREE CASH FLOW | C19: =C18 -> -1042309.3 | D19: =D18 -> -4375963.9 | E19: =E16-E13-E17 -> 1124125.9 | F19: =F16-F13-F17 -> 1545165.6 | G19: =G16-G13-G17 -> 1714540.6 | H19: =H16-H13-H17 -> 1900853.2 | I19: =I16-I13-I17 -> 2535903.7
A20: Cumulative Cash Flow | C20: =C19 -> -1042309.3 | D20: =sum(C20,D19) -> -5418273.2 | E20: =sum(D20,E19) -> -4294147.3 | F20: =sum(E20,F19) -> -2748981.8 | G20: =sum(F20,G19) -> -1034441.1 | H20: =sum(G20,H19) -> 866412.11 | I20: =sum(H20,I19) -> 3402315.8
A22: NPV | B22: {=NPV(L5, D19:I19) + C19} -> 852263.25
A23: IRR | B23: =irr(C19:I19) -> 0.1528805
A24: Payback Period | B24: ~4.5 years
A26: Total investments: | B26: =Invesment!C14 -> 5418273.2
A27: Total net cash inflow: | B27: =sum(E19:I19) -> 8820589
A28: Net benefit: | B28: =B27-B26 -> 3402315.8
A29: ROI: | B29: =B28/B26 -> 0.6279336
A33: Scenario 2 (Digital product) | K33: Key assumptions
B34: 2017(Actual) | C34: 2018(Campaign) | D34: 2019(Campaign) | E34: 2020(Proj.) | F34: 2021(Proj.) | G34: 2022(Proj.) | H34: 2023(Proj.) | I34: 2024(Proj.) | K34: Tax rate: 15% | L34: 0.15
B35: Baseline | C35: 0 | D35: 1 | E35: 2 | F35: 3 | G35: 4 | H35: 5 | I35: 6 | K35: Discount rate: | L35: 0.1
A36: Base sales revenue | B36: ='Income Statement'!E5 -> 4414253.6 | C36: =B36*1.1 -> 4855679 | D36: =C36*1.1 -> 5341246.9 | E36: =D36*1.1 -> 5875371.6 | F36: =E36*1.1 -> 6462908.8 | G36: =F36*1.1 -> 7109199.6 | H36: =G36*1.1 -> 7820119.6 | I36: =H36*1.1 -> 8602131.6 | K36: Incremental Marketing: (campaign years included in €8m) | L36: €1,000,000 from 2020
A37: Project Sales Revenue | B37: ='Income Statement'!E5 -> 4414253.6 | C37: =B37*1.3 -> 5738529.7 | D37: =C37*1.3 -> 7460088.7 | E37: =D37*1.15 -> 8579102 | F37: =E37*1.15 -> 9865967.3 | G37: =F37*1.15 -> 11345862 | H37: =G37*1.15 -> 13047742 | I37: =H37*1.15 -> 15004903 | K37: Incremental employees: | L37: 10
A38: Revenue Growth % | C38: 30%(campaign) | D38: 30%(campaign) | E38: 0.15 | F38: 0.15 | G38: 0.15 | H38: 0.15 | I38: 0.15 | K38: Evaluation: | L38: 7 years (2018–2024)
A39: Incremental Revenue | C39: =C37-C36 -> 882850.73 | D39: =D37-D36 -> 2118841.8 | E39: =E37-E36 -> 2703730.4 | F39: =F37-F36 -> 3403058.5 | G39: =G37-G36 -> 4236662.7 | H39: =H37-H36 -> 5227622.1 | I39: =I37-I36 -> 6402771.4 | K39: Baseline revenue growth (no project): | L39: 10% (same as Scenario 1)
A40: Other variable operating costs (20%) | C40: =C39*(-0.2) -> -176570.15 | D40: =D39*(-0.2) -> -423768.35 | E40: =E39*(-0.2) -> -540746.07 | F40: =F39*(-0.2) -> -680611.7 | G40: =G39*(-0.2) -> -847332.54 | H40: =H39*(-0.2) -> -1045524.4 | I40: =I39*(-0.2) -> -1280554.3 | K40: Salary expense: | L40: 456160
A41: Incremental Marketing | E41: -1000000 | F41: -1000000 | G41: -1000000 | H41: -1000000 | I41: -1000000 | K41: Depreciation: | L41: 0
A42: Total Variable Costs | C42: =C40 -> -176570.15 | D42: =D40 -> -423768.35 | E42: =E40 -> -540746.07 | F42: =F40 -> -680611.7 | G42: =G40 -> -847332.54 | H42: =H40 -> -1045524.4 | I42: =I40 -> -1280554.3
A43: Salary Expense | C43: =-$L$2*2*10 -> -456160 | D43: =-$L$2*2*10 -> -456160 | E43: =-$L$2*2*10 -> -456160 | F43: =-$L$2*2*10 -> -456160 | G43: =-$L$2*2*10 -> -456160 | H43: =-$L$2*2*10 -> -456160 | I43: =-$L$2*2*10 -> -456160
A44: Incremental EBITDA | C44: =C39+C41+C42+C43 -> 250120.58 | D44: =D39+D41+D42+D43 -> 1238913.4 | E44: =E39+E41+E42+E43 -> 706824.29 | F44: =F39+F41+F42+F43 -> 1266286.8 | G44: =G39+G41+G42+G43 -> 1933170.2 | H44: =H39+H41+H42+H43 -> 2725937.7 | I44: =I39+I41+I42+I43 -> 3666057.1
A45: TAX 15% | C45: =-C44*0.15 -> -37518.088 | D45: =-D44*0.15 -> -185837.01 | E45: =-E44*0.15 -> -106023.64 | F45: =-F44*0.15 -> -189943.02 | G45: =-G44*0.15 -> -289975.52 | H45: =-H44*0.15 -> -408890.65 | I45: =-I44*0.15 -> -549908.57
...

Sheet Overview
C23: Metric | D23: Scenario 1 – Factory Expansion | E23: Scenario 2 – Digital Product
C24: Initial Investment (EUR) | D24: 5418273 | E24: 8000000
C25: NPV (10%, EUR) | D25: 852263 | E25: -841203.93
C26: IRR (%) | D26: 0.1528805 | E26: 0.063849321
C27: Payback Period (years) | D27: ~4.5 | E27: ~5.35
C28: ROI (%) | D28: 0.6279336 | E28: 0.094191829
C29: Cumulative FCF (2024, EUR) | D29: 3.40m | E29: 2.02m
C30: Value Creation | D30: Yes | E30: No
C31: Risk Profile | D31: Moderate | E31: Higher
C32: Overall Assessment | D32: Preferred option | E32: Not recommended

Sheet Sheet4
A1: Year | B1: Scenario 1 FCF | C1: Scenario 2 FCF | E1: Year | F1: Scenario 1 – Cumulative FCF | G1: Scenario 2 – Cumulative FCF | I1: Metric | J1: Scenario 1 | K1: Scenario 2
A2: 2018 | B2: -1042309 | C2: -3787398 | E2: 2018 | F2: -1042309 | G2: -3787398 | I2: NPV (EUR) | J2: 852000 | K2: -841204
A3: 2019 | B3: -4375964 | C3: -2946924 | E3: 2019 | F3: -5418273 | G3: -6734322 | I3: IRR (%) | J3: 0.153 | K3: 0.091
A4: 2020 | B4: 1124126 | C4: 600801 | E4: 2020 | F4: -4294147 | G4: -6133521
A5: 2021 | B5: 1545166 | C5: 1076344 | E5: 2021 | F5: -2748981 | G5: -5057177
A6: 2022 | B6: 1714541 | C6: 1643195 | E6: 2022 | F6: -1034440 | G6: -3413982
A7: 2023 | B7: 1900853 | C7: 2317047 | E7: 2023 | F7: 866413 | G7: -1096935
A8: 2024 | B8: 2535904 | C8: 3116149 | E8: 2024 | F8: 3402317 | G8: 2019214
